Workbook

Sheet Form Responses 9
A1: Timestamp | B1: Name | C1: Company | D1: Email | E1: WhatsApp
A2: 46217.773 | B2: Madhan Prasad | C2: Recal | D2: madhanprasad0.5@gmail.com | E2: +91 8015401278
A3: 46228.34 | B3: Boniface Nkunda | C3: Africanenvironments | D3: bonifacenkunda@yahoo.com | E3: +255757430937
A4: 46228.363 | B4: Gladness Tillya | C4: bonadventureafrica.com | D4: gladness.tillya@outlook.com | E4: +255622230231

Sheet Form Responses 2
A1: Timestamp | B1: First Name | C1: Last Name | D1: Email | E1: My Current Goal is: | F1: BOLT Score | G1: CO2TT Score | H1: MBT Score | I1: LOM Zones | J1: ROM Percentage | K1: Tell us more about your goal: | L1: 1BT Score | M1: Age | N1: Gender | O1: Recal ID | P1: Calculated Summit-Ready Score | Q1: Calculated Grade | R1: Calculated Badge
A2: 45912.524 | B2: Bryan | C2: Connelly | D2: bryancconnelly@gmail.com | E2: Improve running | F2: 20 | G2: 42 | H2: 40 | I2: Zone 1 and a bit of Zone 2, Belly movement apparent | J2: 75 | O2: {=IF(A2:A241="",, XLOOKUP(D2:D241, 'Recal IDs Log'!E2:E241, 'Recal IDs Log'!B2:B241, "", 0, -1))} -> #REF! | P2: =IF(A2="",,IF(ISNUMBER(L2), LET(bolt_score, F2, co2tt_score, G2, mbt_score, H2, lom_text, I2, balloon_score, L2, age, M2, bolt_tier, IFS(bolt_score<15,0, bolt_score<20,1, bolt_score<25,2, bolt_score<30,3, bolt_score<35,4, bolt_score>=35,5), co2tt_tier, IFS(co2tt_score<25,0, co2tt_score<40,1, co2tt_score<55,2, co2tt_score<70,3, co2tt_score<85,4, co2tt_score>=85,5), mbt_tier, IFS(mbt_score<25,0, mbt_score<40,1, mbt_score<55,2, mbt_score<70,3, mbt_score<85,4, mbt_score>=85,5), lom_tier, IFS(ISNUMBER(SEARCH("360",lom_text)),5, ISNUMBER(SEARCH("horizontal",lom_text)),4, ISNUMBER(SEARCH("1 & 2",lom_text)),3, ISNUMBER(SEARCH("2 Only",lom_text)),2, ISNUMBER(SEARCH("3 & 2",lom_text)),1, TRUE, 0), bal_raw, IFS(balloon_score<7,0, balloon_score<11,1, balloon_score<14,2, balloon_score<17,3, balloon_score<19,4, balloon_score>=19,5), bal_tier, IF(age>65, MIN(bal_raw+1, 5), bal_raw), total_weighted, (bolt_tier*1) + (co2tt_tier*2) + (mbt_tier*3) + (lom_tier*2) + (bal_tier*2), ROUND((total_weighted/50)*100,0)), LET(bolt_score,F2,co2tt_score,G2,mbt_score,H2,lom_text,I2,rom_score,J2,bolt_tier,IFS(bolt_score<15,0,bolt_score<=19,1,bolt_score<=24,2,bolt_score<=29,3,bolt_score<=34,4,bolt_score>=35,5,TRUE,0),co2tt_tier,IFS(co2tt_score<25,0,co2tt_score<=39,1,co2tt_score<=54,2,co2tt_score<=69,3,co2tt_score<=84,4,co2tt_score>=85,5,TRUE,0),mbt_tier,IFS(mbt_score<25,0,mbt_score<=39,1,mbt_score<=54,2,mbt_score<=69,3,mbt_score<=84,4,mbt_score>=85,5,TRUE,0),rom_tier,IFS(rom_score<60,0,rom_score<=74,1,rom_score<=89,2,rom_score<=104,3,rom_score<=119,4,rom_score>=120,5,TRUE,0),lom_tier,IFS(ISNUMBER(SEARCH("zone 3 only",lom_text)),0,ISNUMBER(SEARCH("zone 3",lom_text))*ISNUMBER(SEARCH("zone 2",lom_text)),1,ISNUMBER(SEARCH("zone 2",lom_text))*NOT(ISNUMBER(SEARCH("zone 1",lom_text)))*NOT(ISNUMBER(SEARCH("zone 3",lom_text))),2,ISNUMBER(SEARCH("zone 1",lom_text))*ISNUMBER(SEARCH("zone 2",lom_text)),3,ISNUMBER(SEARCH("zone 1",lom_text))*ISNUMBER(SEARCH("horizontal",lom_text)),4,ISNUMBER(SEARCH("360",lom_text)),5,TRUE,0),total_weighted_score,(bolt_tier*1)+(co2tt_tier*2)+(mbt_tier*3)+(lom_tier*3)+(rom_tier*1),ROUND((total_weighted_score/50)*100,0)))) -> 46 | Q2: =IF(P2="",,IFS(P2>=93,"Ultra",P2>=80,"Great",P2>=65,"Good",P2>=50,"Fair",P2>=31,"Poor",P2>=0,"Very Poor")) -> Poor | R2: =IF(P2="",,IFS(P2>=93,"Breath Master",P2>=80,"Breathwork-Trained",P2>=65,"Functional Breather",P2>=50,"Breather-in-Training",P2>=31,"Breath Beginner",P2>=0,"Breath-Aware")) -> Breath Beginner
A3: 45912.66 | B3: Anthony | C3: DiFrancesco | D3: acdifran@gmail.com | E3: General breathing improvement | F3: 26 | G3: 64 | H3: 65 | I3: Zone 1 and a bit of Zone 2, Belly movement apparent | J3: 93.75 | O3: {=IF(A3:A241="",, XLOOKUP(D3:D241, 'Recal IDs Log'!E2:E241, 'Recal IDs Log'!B2:B241, "", 0, -1))} -> #REF! | P3: =IF(A3="",,LET(bolt_score,F3,co2tt_score,G3,mbt_score,H3,lom_text,I3,rom_score,J3,bolt_tier,IFS(bolt_score<15,0,bolt_score<=19,1,bolt_score<=24,2,bolt_score<=29,3,bolt_score<=34,4,bolt_score>=35,5,TRUE,0),co2tt_tier,IFS(co2tt_score<25,0,co2tt_score<=39,1,co2tt_score<=54,2,co2tt_score<=69,3,co2tt_score<=84,4,co2tt_score>=85,5,TRUE,0),mbt_tier,IFS(mbt_score<25,0,mbt_score<=39,1,mbt_score<=54,2,mbt_score<=69,3,mbt_score<=84,4,mbt_score>=85,5,TRUE,0),rom_tier,IFS(rom_score<60,0,rom_score<=74,1,rom_score<=89,2,rom_score<=104,3,rom_score<=119,4,rom_score>=120,5,TRUE,0),lom_tier,IFS(ISNUMBER(SEARCH("zone 3 only",lom_text)),0,ISNUMBER(SEARCH("zone 3",lom_text))*ISNUMBER(SEARCH("zone 2",lom_text)),1,ISNUMBER(SEARCH("zone 2",lom_text))*NOT(ISNUMBER(SEARCH("zone 1",lom_text)))*NOT(ISNUMBER(SEARCH("zone 3",lom_text))),2,ISNUMBER(SEARCH("zone 1",lom_text))*ISNUMBER(SEARCH("zone 2",lom_text)),3,ISNUMBER(SEARCH("zone 1",lom_text))*ISNUMBER(SEARCH("horizontal",lom_text)),4,ISNUMBER(SEARCH("360",lom_text)),5,TRUE,0),total_weighted_score,(bolt_tier*1)+(co2tt_tier*2)+(mbt_tier*3)+(lom_tier*3)+(rom_tier*1),(total_weighted_score/50)*100)) -> 60 | Q3: =IF(P3="",,IFS(P3>=93,"Ultra",P3>=80,"Great",P3>=65,"Good",P3>=50,"Fair",P3>=31,"Poor",P3>=0,"Very Poor")) -> Fair | R3: =IF(P3="",,IFS(P3>=93,"Breath Master",P3>=80,"Breathwork-Trained",P3>=65,"Functional Breather",P3>=50,"Breather-in-Training",P3>=31,"Breath Beginner",P3>=0,"Breath-Aware")) -> Breather-in-Training
A4: 45912.806 | B4: Joe | C4: Hayden | D4: ljhaydn@gmail.com | E4: general fitness | F4: 21 | G4: 48 | H4: 45 | I4: Zone 1 and a bit of Zone 2, Belly movement apparent | J4: 140 | O4: {=IF(A4:A241="",, XLOOKUP(D4:D241, 'Recal IDs Log'!E3:E241, 'Recal IDs Log'!B3:B241, "", 0, -1))} -> #REF! | P4: =IF(A4="",,LET(bolt_score,F4,co2tt_score,G4,mbt_score,H4,lom_text,I4,rom_score,J4,bolt_tier,IFS(bolt_score<15,0,bolt_score<=19,1,bolt_score<=24,2,bolt_score<=29,3,bolt_score<=34,4,bolt_score>=35,5,TRUE,0),co2tt_tier,IFS(co2tt_score<25,0,co2tt_score<=39,1,co2tt_score<=54,2,co2tt_score<=69,3,co2tt_score<=84,4,co2tt_score>=85,5,TRUE,0),mbt_tier,IFS(mbt_score<25,0,mbt_score<=39,1,mbt_score<=54,2,mbt_score<=69,3,mbt_score<=84,4,mbt_score>=85,5,TRUE,0),rom_tier,IFS(rom_score<60,0,rom_score<=74,1,rom_score<=89,2,rom_score<=104,3,rom_score<=119,4,rom_score>=120,5,TRUE,0),lom_tier,IFS(ISNUMBER(SEARCH("zone 3 only",lom_text)),0,ISNUMBER(SEARCH("zone 3",lom_text))*ISNUMBER(SEARCH("zone 2",lom_text)),1,ISNUMBER(SEARCH("zone 2",lom_text))*NOT(ISNUMBER(SEARCH("zone 1",lom_text)))*NOT(ISNUMBER(SEARCH("zone 3",lom_text))),2,ISNUMBER(SEARCH("zone 1",lom_text))*ISNUMBER(SEARCH("zone 2",lom_text)),3,ISNUMBER(SEARCH("zone 1",lom_text))*ISNUMBER(SEARCH("horizontal",lom_text)),4,ISNUMBER(SEARCH("360",lom_text)),5,TRUE,0),total_weighted_score,(bolt_tier*1)+(co2tt_tier*2)+(mbt_tier*3)+(lom_tier*3)+(rom_tier*1),(total_weighted_score/50)*100)) -> 52 | Q4: =IF(P4="",,IFS(P4>=93,"Ultra",P4>=80,"Great",P4>=65,"Good",P4>=50,"Fair",P4>=31,"Poor",P4>=0,"Very Poor")) -> Fair | R4: =IF(P4="",,IFS(P4>=93,"Breath Master",P4>=80,"Breathwork-Trained",P4>=65,"Functional Breather",P4>=50,"Breather-in-Training",P4>=31,"Breath Beginner",P4>=0,"Breath-Aware")) -> Breather-in-Training
A5: 45912.813 | B5: Tracy | C5: Penrose | D5: penrose815@gmail.com | E5: To hike 1 mile in Alaska rainforest | F5: 27 | G5: 53 | H5: 38 | I5: Zone 1 and a bit of Zone 2, Belly movement apparent | J5: 64.28 | O5: {=IF(A5:A241="",, XLOOKUP(D5:D241, 'Recal IDs Log'!E4:E241, 'Recal IDs Log'!B4:B241, "", 0, -1))} -> #REF! | P5: =IF(A5="",,LET(bolt_score,F5,co2tt_score,G5,mbt_score,H5,lom_text,I5,rom_score,J5,bolt_tier,IFS(bolt_score<15,0,bolt_score<=19,1,bolt_score<=24,2,bolt_score<=29,3,bolt_score<=34,4,bolt_score>=35,5,TRUE,0),co2tt_tier,IFS(co2tt_score<25,0,co2tt_score<=39,1,co2tt_score<=54,2,co2tt_score<=69,3,co2tt_score<=84,4,co2tt_score>=85,5,TRUE,0),mbt_tier,IFS(mbt_score<25,0,mbt_score<=39,1,mbt_score<=54,2,mbt_score<=69,3,mbt_score<=84,4,mbt_score>=85,5,TRUE,0),rom_tier,IFS(rom_score<60,0,rom_score<=74,1,rom_score<=89,2,rom_score<=104,3,rom_score<=119,4,rom_score>=120,5,TRUE,0),lom_tier,IFS(ISNUMBER(SEARCH("zone 3 only",lom_text)),0,ISNUMBER(SEARCH("zone 3",lom_text))*ISNUMBER(SEARCH("zone 2",lom_text)),1,ISNUMBER(SEARCH("zone 2",lom_text))*NOT(ISNUMBER(SEARCH("zone 1",lom_text)))*NOT(ISNUMBER(SEARCH("zone 3",lom_text))),2,ISNUMBER(SEARCH("zone 1",lom_text))*ISNUMBER(SEARCH("zone 2",lom_text)),3,ISNUMBER(SEARCH("zone 1",lom_text))*ISNUMBER(SEARCH("horizontal",lom_text)),4,ISNUMBER(SEARCH("360",lom_text)),5,TRUE,0),total_weighted_score,(bolt_tier*1)+(co2tt_tier*2)+(mbt_tier*3)+(lom_tier*3)+(rom_tier*1),(total_weighted_score/50)*100)) -> 40 | Q5: =IF(P5="",,IFS(P5>=93,"Ultra",P5>=80,"Great",P5>=65,"Good",P5>=50,"Fair",P5>=31,"Poor",P5>=0,"Very Poor")) -> Poor | R5: =IF(P5="",,IFS(P5>=93,"Breath Master",P5>=80,"Breathwork-Trained",P5>=65,"Functional Breather",P5>=50,"Breather-in-Training",P5>=31,"Breath Beginner",P5>=0,"Breath-Aware")) -> Breath Beginner
A6: 45912.821 | B6: Carl | C6: Lorubbio | D6: clorubbio@aol.com | E6: Not training at this time | F6: 22 | G6: 54 | H6: 36 | I6: Zone 1 and a bit of Zone 2, Belly movement apparent | J6: 123 | O6: {=IF(A6:A241="",, XLOOKUP(D6:D241, 'Recal IDs Log'!E5:E241, 'Recal IDs Log'!B5:B241, "", 0, -1))} -> #REF! | P6: =IF(A6="",,LET(bolt_score,F6,co2tt_score,G6,mbt_score,H6,lom_text,I6,rom_score,J6,bolt_tier,IFS(bolt_score<15,0,bolt_score<=19,1,bolt_score<=24,2,bolt_score<=29,3,bolt_score<=34,4,bolt_score>=35,5,TRUE,0),co2tt_tier,IFS(co2tt_score<25,0,co2tt_score<=39,1,co2tt_score<=54,2,co2tt_score<=69,3,co2tt_score<=84,4,co2tt_score>=85,5,TRUE,0),mbt_tier,IFS(mbt_score<25,0,mbt_score<=39,1,mbt_score<=54,2,mbt_score<=69,3,mbt_score<=84,4,mbt_score>=85,5,TRUE,0),rom_tier,IFS(rom_score<60,0,rom_score<=74,1,rom_score<=89,2,rom_score<=104,3,rom_score<=119,4,rom_score>=120,5,TRUE,0),lom_tier,IFS(ISNUMBER(SEARCH("zone 3 only",lom_text)),0,ISNUMBER(SEARCH("zone 3",lom_text))*ISNUMBER(SEARCH("zone 2",lom_text)),1,ISNUMBER(SEARCH("zone 2",lom_text))*NOT(ISNUMBER(SEARCH("zone 1",lom_text)))*NOT(ISNUMBER(SEARCH("zone 3",lom_text))),2,ISNUMBER(SEARCH("zone 1",lom_text))*ISNUMBER(SEARCH("zone 2",lom_text)),3,ISNUMBER(SEARCH("zone 1",lom_text))*ISNUMBER(SEARCH("horizontal",lom_text)),4,ISNUMBER(SEARCH("360",lom_text)),5,TRUE,0),total_weighted_score,(bolt_tier*1)+(co2tt_tier*2)+(mbt_tier*3)+(lom_tier*3)+(rom_tier*1),(total_weighted_score/50)*100)) -> 46 | Q6: =IF(P6="",,IFS(P6>=93,"Ultra",P6>=80,"Great",P6>=65,"Good",P6>=50,"Fair",P6>=31,"Poor",P6>=0,"Very Poor")) -> Poor | R6: =IF(P6="",,IFS(P6>=93,"Breath Master",P6>=80,"Breathwork-Trained",P6>=65,"Functional Breather",P6>=50,"Breather-in-Training",P6>=31,"Breath Beginner",P6>=0,"Breath-Aware")) -> Breath Beginner
A7: 45912.833 | B7: Joe | C7: Hayden | D7: ljhaydn@gmail.com | E7: not dying | F7: 0 | G7: 0 | H7: 0 | I7: Zone 3 only, Vertical movement | J7: 0 | O7: {=IF(A7:A241="",, XLOOKUP(D7:D241, 'Recal IDs Log'!E6:E241, 'Recal IDs Log'!B6:B241, "", 0, -1))} -> #REF! | P7: =IF(A7="",,LET(bolt_score,F7,co2tt_score,G7,mbt_score,H7,lom_text,I7,rom_score,J7,bolt_tier,IFS(bolt_score<15,0,bolt_score<=19,1,bolt_score<=24,2,bolt_score<=29,3,bolt_score<=34,4,bolt_score>=35,5,TRUE,0),co2tt_tier,IFS(co2tt_score<25,0,co2tt_score<=39,1,co2tt_score<=54,2,co2tt_score<=69,3,co2tt_score<=84,4,co2tt_score>=85,5,TRUE,0),mbt_tier,IFS(mbt_score<25,0,mbt_score<=39,1,mbt_score<=54,2,mbt_score<=69,3,mbt_score<=84,4,mbt_score>=85,5,TRUE,0),rom_tier,IFS(rom_score<60,0,rom_score<=74,1,rom_score<=89,2,rom_score<=104,3,rom_score<=119,4,rom_score>=120,5,TRUE,0),lom_tier,IFS(ISNUMBER(SEARCH("zone 3 only",lom_text)),0,ISNUMBER(SEARCH("zone 3",lom_text))*ISNUMBER(SEARCH("zone 2",lom_text)),1,ISNUMBER(SEARCH("zone 2",lom_text))*NOT(ISNUMBER(SEARCH("zone 1",lom_text)))*NOT(ISNUMBER(SEARCH("zone 3",lom_text))),2,ISNUMBER(SEARCH("zone 1",lom_text))*ISNUMBER(SEARCH("zone 2",lom_text)),3,ISNUMBER(SEARCH("zone 1",lom_text))*ISNUMBER(SEARCH("horizontal",lom_text)),4,ISNUMBER(SEARCH("360",lom_text)),5,TRUE,0),total_weighted_score,(bolt_tier*1)+(co2tt_tier*2)+(mbt_tier*3)+(lom_tier*3)+(rom_tier*1),(total_weighted_score/50)*100)) -> 0 | Q7: =IF(P7="",,IFS(P7>=93,"Ultra",P7>=80,"Great",P7>=65,"Good",P7>=50,"Fair",P7>=31,"Poor",P7>=0,"Very Poor")) -> Very Poor | R7: =IF(P7="",,IFS(P7>=93,"Breath Master",P7>=80,"Breathwork-Trained",P7>=65,"Functional Breather",P7>=50,"Breather-in-Training",P7>=31,"Breath Beginner",P7>=0,"Breath-Aware")) -> Breath-Aware
A8: 45912.874 | B8: Sara | C8: Crawford | D8: sara.crawford95@yahoo.com | E8: General hiking fitness | F8: 20 | G8: 30 | H8: 47 | I8: Zone 1 and a bit of Zone 2, Belly movement apparent | J8: 95 | O8: {=IF(A8:A241="",, XLOOKUP(D8:D241, 'Recal IDs Log'!E7:E241, 'Recal IDs Log'!B7:B241, "", 0, -1))} -> #REF! | P8: =IF(A8="",,LET(bolt_score,F8,co2tt_score,G8,mbt_score,H8,lom_text,I8,rom_score,J8,bolt_tier,IFS(bolt_score<15,0,bolt_score<=19,1,bolt_score<=24,2,bolt_score<=29,3,bolt_score<=34,4,bolt_score>=35,5,TRUE,0),co2tt_tier,IFS(co2tt_score<25,0,co2tt_score<=39,1,co2tt_score<=54,2,co2tt_score<=69,3,co2tt_score<=84,4,co2tt_score>=85,5,TRUE,0),mbt_tier,IFS(mbt_score<25,0,mbt_score<=39,1,mbt_score<=54,2,mbt_score<=69,3,mbt_score<=84,4,mbt_score>=85,5,TRUE,0),rom_tier,IFS(rom_score<60,0,rom_score<=74,1,rom_score<=89,2,rom_score<=104,3,rom_score<=119,4,rom_score>=120,5,TRUE,0),lom_tier,IFS(ISNUMBER(SEARCH("zone 3 only",lom_text)),0,ISNUMBER(SEARCH("zone 3",lom_text))*ISNUMBER(SEARCH("zone 2",lom_text)),1,ISNUMBER(SEARCH("zone 2",lom_text))*NOT(ISNUMBER(SEARCH("zone 1",lom_text)))*NOT(ISNUMBER(SEARCH("zone 3",lom_text))),2,ISNUMBER(SEARCH("zone 1",lom_text))*ISNUMBER(SEARCH("zone 2",lom_text)),3,ISNUMBER(SEARCH("zone 1",lom_text))*ISNUMBER(SEARCH("horizontal",lom_text)),4,ISNUMBER(SEARCH("360",lom_text)),5,TRUE,0),total_weighted_score,(bolt_tier*1)+(co2tt_tier*2)+(mbt_tier*3)+(lom_tier*3)+(rom_tier*1),(total_weighted_score/50)*100)) -> 44 | Q8: =IF(P8="",,IFS(P8>=93,"Ultra",P8>=80,"Great",P8>=65,"Good",P8>=50,"Fair",P8>=31,"Poor",P8>=0,"Very Poor")) -> Poor | R8: =IF(P8="",,IFS(P8>=93,"Breath Master",P8>=80,"Breathwork-Trained",P8>=65,"Functional Breather",P8>=50,"Breather-in-Training",P8>=31,"Breath Beginner",P8>=0,"Breath-Aware")) -> Breath Beginner
A9: 45915.748 | B9: Brian | C9: Passenti | D9: brian@altitudeendurancecoaching.com | E9: Life! and a few ultras... | F9: 26 | G9: 47 | H9: 48 | I9: Zone 1, Horizontal movement, Shoulders = no movement | J9: 96.1 | O9: {=IF(A9:A241="",, XLOOKUP(D9:D241, 'Recal IDs Log'!E8:E241, 'Recal IDs Log'!B8:B241, "", 0, -1))} -> #REF! | P9: =IF(A9="",,LET(bolt_score,F9,co2tt_score,G9,mbt_score,H9,lom_text,I9,rom_score,J9,bolt_tier,IFS(bolt_score<15,0,bolt_score<=19,1,bolt_score<=24,2,bolt_score<=29,3,bolt_score<=34,4,bolt_score>=35,5,TRUE,0),co2tt_tier,IFS(co2tt_score<25,0,co2tt_score<=39,1,co2tt_score<=54,2,co2tt_score<=69,3,co2tt_score<=84,4,co2tt_score>=85,5,TRUE,0),mbt_tier,IFS(mbt_score<25,0,mbt_score<=39,1,mbt_score<=54,2,mbt_score<=69,3,mbt_score<=84,4,mbt_score>=85,5,TRUE,0),rom_tier,IFS(rom_score<60,0,rom_score<=74,1,rom_score<=89,2,rom_score<=104,3,rom_score<=119,4,rom_score>=120,5,TRUE,0),lom_tier,IFS(ISNUMBER(SEARCH("zone 3 only",lom_text)),0,ISNUMBER(SEARCH("zone 3",lom_text))*ISNUMBER(SEARCH("zone 2",lom_text)),1,ISNUMBER(SEARCH("zone 2",lom_text))*NOT(ISNUMBER(SEARCH("zone 1",lom_text)))*NOT(ISNUMBER(SEARCH("zone 3",lom_text))),2,ISNUMBER(SEARCH("zone 1",lom_text))*ISNUMBER(SEARCH("zone 2",lom_text)),3,ISNUMBER(SEARCH("zone 1",lom_text))*ISNUMBER(SEARCH("horizontal",lom_text)),4,ISNUMBER(SEARCH("360",lom_text)),5,TRUE,0),total_weighted_score,(bolt_tier*1)+(co2tt_tier*2)+(mbt_tier*3)+(lom_tier*3)+(rom_tier*1),(total_weighted_score/50)*100)) -> 56 | Q9: =IF(P9="",,IFS(P9>=93,"Ultra",P9>=80,"Great",P9>=65,"Good",P9>=50,"Fair",P9>=31,"Poor",P9>=0,"Very Poor")) -> Fair | R9: =IF(P9="",,IFS(P9>=93,"Breath Master",P9>=80,"Breathwork-Trained",P9>=65,"Functional Breather",P9>=50,"Breather-in-Training",P9>=31,"Breath Beginner",P9>=0,"Breath-Aware")) -> Breather-in-Training
A10: 45915.808 | B10: Kate | C10: McIver | D10: katelmciver@gmail.com | E10: Give birth 🤣 wonder how different these would have been before I was 5 months pregnant. | F10: 10 | G10: 29.75 | H10: 20 | I10: Zone 1, Horizontal movement, Shoulders = no movement | J10: 47.6 | O10: {=IF(A10:A241="",, XLOOKUP(D10:D241, 'Recal IDs Log'!E9:E241, 'Recal IDs Log'!B9:B241, "", 0, -1))} -> #REF! | P10: =IF(A10="",,LET(bolt_score,F10,co2tt_score,G10,mbt_score,H10,lom_text,I10,rom_score,J10,bolt_tier,IFS(bolt_score<15,0,bolt_score<=19,1,bolt_score<=24,2,bolt_score<=29,3,bolt_score<=34,4,bolt_score>=35,5,TRUE,0),co2tt_tier,IFS(co2tt_score<25,0,co2tt_score<=39,1,co2tt_score<=54,2,co2tt_score<=69,3,co2tt_score<=84,4,co2tt_score>=85,5,TRUE,0),mbt_tier,IFS(mbt_score<25,0,mbt_score<=39,1,mbt_score<=54,2,mbt_score<=69,3,mbt_score<=84,4,mbt_score>=85,5,TRUE,0),rom_tier,IFS(rom_score<60,0,rom_score<=74,1,rom_score<=89,2,rom_score<=104,3,rom_score<=119,4,rom_score>=120,5,TRUE,0),lom_tier,IFS(ISNUMBER(SEARCH("zone 3 only",lom_text)),0,ISNUMBER(SEARCH("zone 3",lom_text))*ISNUMBER(SEARCH("zone 2",lom_text)),1,ISNUMBER(SEARCH("zone 2",lom_text))*NOT(ISNUMBER(SEARCH("zone 1",lom_text)))*NOT(ISNUMBER(SEARCH("zone 3",lom_text))),2,ISNUMBER(SEARCH("zone 1",lom_text))*ISNUMBER(SEARCH("zone 2",lom_text)),3,ISNUMBER(SEARCH("zone 1",lom_text))*ISNUMBER(SEARCH("horizontal",lom_text)),4,ISNUMBER(SEARCH("360",lom_text)),5,TRUE,0),total_weighted_score,(bolt_tier*1)+(co2tt_tier*2)+(mbt_tier*3)+(lom_tier*3)+(rom_tier*1),(total_weighted_score/50)*100)) -> 28 | Q10: =IF(P10="",,IFS(P10>=93,"Ultra",P10>=80,"Great",P10>=65,"Good",P10>=50,"Fair",P10>=31,"Poor",P10>=0,"Very Poor")) -> Very Poor | R10: =IF(P10="",,IFS(P10>=93,"Breath Master",P10>=80,"Breathwork-Trained",P10>=65,"Functional Breather",P10>=50,"Breather-in-Training",P10>=31,"Breath Beginner",P10>=0,"Breath-Aware")) -> Breath-Aware
A11: 45915.815 | B11: Pedro | C11: Kroeff | D11: pedroakroeff@gmail.com | E11: maximize the time i can beat 20 year olds in pickup hoops | F11: 17 | G11: 61 | H11: 30 | I11: Zone 1 and a bit of Zone 2, Belly movement apparent | J11: 38.5 | O11: {=IF(A11:A241="",, XLOOKUP(D11:D241, 'Recal IDs Log'!E10:E241, 'Recal IDs Log'!B10:B241, "", 0, -1))} -> #REF! | P11: =IF(A11="",,LET(bolt_score,F11,co2tt_score,G11,mbt_score,H11,lom_text,I11,rom_score,J11,bolt_tier,IFS(bolt_score<15,0,bolt_score<=19,1,bolt_score<=24,2,bolt_score<=29,3,bolt_score<=34,4,bolt_score>=35,5,TRUE,0),co2tt_tier,IFS(co2tt_score<25,0,co2tt_score<=39,1,co2tt_score<=54,2,co2tt_score<=69,3,co2tt_score<=84,4,co2tt_score>=85,5,TRUE,0),mbt_tier,IFS(mbt_score<25,0,mbt_score<=39,1,mbt_score<=54,2,mbt_score<=69,3,mbt_score<=84,4,mbt_score>=85,5,TRUE,0),rom_tier,IFS(rom_score<60,0,rom_score<=74,1,rom_score<=89,2,rom_score<=104,3,rom_score<=119,4,rom_score>=120,5,TRUE,0),lom_tier,IFS(ISNUMBER(SEARCH("zone 3 only",lom_text)),0,ISNUMBER(SEARCH("zone 3",lom_text))*ISNUMBER(SEARCH("zone 2",lom_text)),1,ISNUMBER(SEARCH("zone 2",lom_text))*NOT(ISNUMBER(SEARCH("zone 1",lom_text)))*NOT(ISNUMBER(SEARCH("zone 3",lom_text))),2,ISNUMBER(SEARCH("zone 1",lom_text))*ISNUMBER(SEARCH("zone 2",lom_text)),3,ISNUMBER(SEARCH("zone 1",lom_text))*ISNUMBER(SEARCH("horizontal",lom_text)),4,ISNUMBER(SEARCH("360",lom_text)),5,TRUE,0),total_weighted_score,(bolt_tier*1)+(co2tt_tier*2)+(mbt_tier*3)+(lom_tier*3)+(rom_tier*1),(total_weighted_score/50)*100)) -> 38 | Q11: =IF(P11="",,IFS(P11>=93,"Ultra",P11>=80,"Great",P11>=65,"Good",P11>=50,"Fair",P11>=31,"Poor",P11>=0,"Very Poor")) -> Poor | R11: =IF(P11="",,IFS(P11>=93,"Breath Master",P11>=80,"Breathwork-Trained",P11>=65,"Functional Breather",P11>=50,"Breather-in-Training",P11>=31,"Breath Beginner",P11>=0,"Breath-Aware")) -> Breath Beginner
A12: 45915.897 | B12: Owen | C12: Parker | D12: daniel.owen.parker@gmail.com | E12: half marathon in 10mnths | F12: 21 | G12: 42 | H12: 30 | I12: Zone 1 and a bit of Zone 2, Belly movement apparent | J12: 45 | O12: {=IF(A12:A241="",, XLOOKUP(D12:D241, 'Recal IDs Log'!E11:E241, 'Recal IDs Log'!B11:B241, "", 0, -1))} -> #REF! | P12: =IF(A12="",,LET(bolt_score,F12,co2tt_score,G12,mbt_score,H12,lom_text,I12,rom_score,J12,bolt_tier,IFS(bolt_score<15,0,bolt_score<=19,1,bolt_score<=24,2,bolt_score<=29,3,bolt_score<=34,4,bolt_score>=35,5,TRUE,0),co2tt_tier,IFS(co2tt_score<25,0,co2tt_score<=39,1,co2tt_score<=54,2,co2tt_score<=69,3,co2tt_score<=84,4,co2tt_score>=85,5,TRUE,0),mbt_tier,IFS(mbt_score<25,0,mbt_score<=39,1,mbt_score<=54,2,mbt_score<=69,3,mbt_score<=84,4,mbt_score>=85,5,TRUE,0),rom_tier,IFS(rom_score<60,0,rom_score<=74,1,rom_score<=89,2,rom_score<=104,3,rom_score<=119,4,rom_score>=120,5,TRUE,0),lom_tier,IFS(ISNUMBER(SEARCH("zone 3 only",lom_text)),0,ISNUMBER(SEARCH("zone 3",lom_text))*ISNUMBER(SEARCH("zone 2",lom_text)),1,ISNUMBER(SEARCH("zone 2",lom_text))*NOT(ISNUMBER(SEARCH("zone 1",lom_text)))*NOT(ISNUMBER(SEARCH("zone 3",lom_text))),2,ISNUMBER(SEARCH("zone 1",lom_text))*ISNUMBER(SEARCH("zone 2",lom_text)),3,ISNUMBER(SEARCH("zone 1",lom_text))*ISNUMBER(SEARCH("horizontal",lom_text)),4,ISNUMBER(SEARCH("360",lom_text)),5,TRUE,0),total_weighted_score,(bolt_tier*1)+(co2tt_tier*2)+(mbt_tier*3)+(lom_tier*3)+(rom_tier*1),(total_weighted_score/50)*100)) -> 36 | Q12: =IF(P12="",,IFS(P12>=93,"Ultra",P12>=80,"Great",P12>=65,"Good",P12>=50,"Fair",P12>=31,"Poor",P12>=0,"Very Poor")) -> Poor | R12: =IF(P12="",,IFS(P12>=93,"Breath Master",P12>=80,"Breathwork-Trained",P12>=65,"Functional Breather",P12>=50,"Breather-in-Training",P12>=31,"Breath Beginner",P12>=0,"Breath-Aware")) -> Breath Beginner
A13: 45916.144 | B13: Colin | C13: McIver | D13: Colinvmciver@gmail.com | E13: Colin says no goals…plenty awesome as is | F13: 14 | G13: 50 | H13: 28 | I13: Zone 1 and a bit of Zone 2, Belly movement apparent | J13: 78.5 | O13: {=IF(A13:A241="",, XLOOKUP(D13:D241, 'Recal IDs Log'!E12:E241, 'Recal IDs Log'!B12:B241, "", 0, -1))} -> #REF! | P13: =IF(A13="",,LET(bolt_score,F13,co2tt_score,G13,mbt_score,H13,lom_text,I13,rom_score,J13,bolt_tier,IFS(bolt_score<15,0,bolt_score<=19,1,bolt_score<=24,2,bolt_score<=29,3,bolt_score<=34,4,bolt_score>=35,5,TRUE,0),co2tt_tier,IFS(co2tt_score<25,0,co2tt_score<=39,1,co2tt_score<=54,2,co2tt_score<=69,3,co2tt_score<=84,4,co2tt_score>=85,5,TRUE,0),mbt_tier,IFS(mbt_score<25,0,mbt_score<=39,1,mbt_score<=54,2,mbt_score<=69,3,mbt_score<=84,4,mbt_score>=85,5,TRUE,0),rom_tier,IFS(rom_score<60,0,rom_score<=74,1,rom_score<=89,2,rom_score<=104,3,rom_score<=119,4,rom_score>=120,5,TRUE,0),lom_tier,IFS(ISNUMBER(SEARCH("zone 3 only",lom_text)),0,ISNUMBER(SEARCH("zone 3",lom_text))*ISNUMBER(SEARCH("zone 2",lom_text)),1,ISNUMBER(SEARCH("zone 2",lom_text))*NOT(ISNUMBER(SEARCH("zone 1",lom_text)))*NOT(ISNUMBER(SEARCH("zone 3",lom_text))),2,ISNUMBER(SEARCH("zone 1",lom_text))*ISNUMBER(SEARCH("zone 2",lom_text)),3,ISNUMBER(SEARCH("zone 1",lom_text))*ISNUMBER(SEARCH("horizontal",lom_text)),4,ISNUMBER(SEARCH("360",lom_text)),5,TRUE,0),total_weighted_score,(bolt_tier*1)+(co2tt_tier*2)+(mbt_tier*3)+(lom_tier*3)+(rom_tier*1),(total_weighted_score/50)*100)) -> 36 | Q13: =IF(P13="",,IFS(P13>=93,"Ultra",P13>=80,"Great",P13>=65,"Good",P13>=50,"Fair",P13>=31,"Poor",P13>=0,"Very Poor")) -> Poor | R13: =IF(P13="",,IFS(P13>=93,"Breath Master",P13>=80,"Breathwork-Trained",P13>=65,"Functional Breather",P13>=50,"Breather-in-Training",P13>=31,"Breath Beginner",P13>=0,"Breath-Aware")) -> Breath Beginner
A14: 45917.986 | B14: Mariana | C14: Shaw | D14: marianabshaw@gmail.com | E14: Definitely to climb without feeling out of breath | F14: 18 | G14: 53 | H14: 49 | I14: Zone 3, some Zone 2, Shoulder movement apparent | J14: 82.7 | O14: {=IF(A14:A241="",, XLOOKUP(D14:D241, 'Recal IDs Log'!E13:E241, 'Recal IDs Log'!B13:B241, "", 0, -1))} -> #REF! | P14: =IF(A14="",,LET(bolt_score,F14,co2tt_score,G14,mbt_score,H14,lom_text,I14,rom_score,J14,bolt_tier,IFS(bolt_score<15,0,bolt_score<=19,1,bolt_score<=24,2,bolt_score<=29,3,bolt_score<=34,4,bolt_score>=35,5,TRUE,0),co2tt_tier,IFS(co2tt_score<25,0,co2tt_score<=39,1,co2tt_score<=54,2,co2tt_score<=69,3,co2tt_score<=84,4,co2tt_score>=85,5,TRUE,0),mbt_tier,IFS(mbt_score<25,0,mbt_score<=39,1,mbt_score<=54,2,mbt_score<=69,3,mbt_score<=84,4,mbt_score>=85,5,TRUE,0),rom_tier,IFS(rom_score<60,0,rom_score<=74,1,rom_score<=89,2,rom_score<=104,3,rom_score<=119,4,rom_score>=120,5,TRUE,0),lom_tier,IFS(ISNUMBER(SEARCH("zone 3 only",lom_text)),0,ISNUMBER(SEARCH("zone 3",lom_text))*ISNUMBER(SEARCH("zone 2",lom_text)),1,ISNUMBER(SEARCH("zone 2",lom_text))*NOT(ISNUMBER(SEARCH("zone 1",lom_text)))*NOT(ISNUMBER(SEARCH("zone 3",lom_text))),2,ISNUMBER(SEARCH("zone 1",lom_text))*ISNUMBER(SEARCH("zone 2",lom_text)),3,ISNUMBER(SEARCH("zone 1",lom_text))*ISNUMBER(SEARCH("horizontal",lom_text)),4,ISNUMBER(SEARCH("360",lom_text)),5,TRUE,0),total_weighted_score,(bolt_tier*1)+(co2tt_tier*2)+(mbt_tier*3)+(lom_tier*3)+(rom_tier*1),(total_weighted_score/50)*100)) -> 32 | Q14: =IF(P14="",,IFS(P14>=93,"Ultra",P14>=80,"Great",P14>=65,"Good",P14>=50,"Fair",P14>=31,"Poor",P14>=0,"Very Poor")) -> Poor | R14: =IF(P14="",,IFS(P14>=93,"Breath Master",P14>=80,"Breathwork-Trained",P14>=65,"Functional Breather",P14>=50,"Breather-in-Training",P14>=31,"Breath Beginner",P14>=0,"Breath-Aware")) -> Breath Beginner
A15: 45918.045 | B15: Aybuke | C15: Turker | D15: aybketrker@gmail.com | E15: climb at high altitue without feeling out-of-breath | F15: 26 | G15: 42 | H15: 33 | I15: Zone 1 and a bit of Zone 2, Belly movement apparent | J15: 52.6 | O15: {=IF(A15:A241="",, XLOOKUP(D15:D241, 'Recal IDs Log'!E14:E241, 'Recal IDs Log'!B14:B241, "", 0, -1))} -> #REF! | P15: =IF(A15="",,LET(bolt_score,F15,co2tt_score,G15,mbt_score,H15,lom_text,I15,rom_score,J15,bolt_tier,IFS(bolt_score<15,0,bolt_score<=19,1,bolt_score<=24,2,bolt_score<=29,3,bolt_score<=34,4,bolt_score>=35,5,TRUE,0),co2tt_tier,IFS(co2tt_score<25,0,co2tt_score<=39,1,co2tt_score<=54,2,co2tt_score<=69,3,co2tt_score<=84,4,co2tt_score>=85,5,TRUE,0),mbt_tier,IFS(mbt_score<25,0,mbt_score<=39,1,mbt_score<=54,2,mbt_score<=69,3,mbt_score<=84,4,mbt_score>=85,5,TRUE,0),rom_tier,IFS(rom_score<60,0,rom_score<=74,1,rom_score<=89,2,rom_score<=104,3,rom_score<=119,4,rom_score>=120,5,TRUE,0),lom_tier,IFS(ISNUMBER(SEARCH("zone 3 only",lom_text)),0,ISNUMBER(SEARCH("zone 3",lom_text))*ISNUMBER(SEARCH("zone 2",lom_text)),1,ISNUMBER(SEARCH("zone 2",lom_text))*NOT(ISNUMBER(SEARCH("zone 1",lom_text)))*NOT(ISNUMBER(SEARCH("zone 3",lom_text))),2,ISNUMBER(SEARCH("zone 1",lom_text))*ISNUMBER(SEARCH("zone 2",lom_text)),3,ISNUMBER(SEARCH("zone 1",lom_text))*ISNUMBER(SEARCH("horizontal",lom_text)),4,ISNUMBER(SEARCH("360",lom_text)),5,TRUE,0),total_weighted_score,(bolt_tier*1)+(co2tt_tier*2)+(mbt_tier*3)+(lom_tier*3)+(rom_tier*1),(total_weighted_score/50)*100)) -> 38 | Q15: =IF(P15="",,IFS(P15>=93,"Ultra",P15>=80,"Great",P15>=65,"Good",P15>=50,"Fair",P15>=31,"Poor",P15>=0,"Very Poor")) -> Poor | R15: =IF(P15="",,IFS(P15>=93,"Breath Master",P15>=80,"Breathwork-Trained",P15>=65,"Functional Breather",P15>=50,"Breather-in-Training",P15>=31,"Breath Beginner",P15>=0,"Breath-Aware")) -> Breath Beginner
A16: 45918.743 | B16: Alan | C16: Greenberg | D16: greenbergsherpa@mac.com | E16: Ski moguls | F16: 25 | G16: 36 | H16: 65 | I16: Zone 1 and a bit of Zone 2, Belly movement apparent | J16: 57.14 | O16: {=IF(A16:A241="",, XLOOKUP(D16:D241, 'Recal IDs Log'!E15:E241, 'Recal IDs Log'!B15:B241, "", 0, -1))} -> #REF! | P16: =IF(A16="",,LET(bolt_score,F16,co2tt_score,G16,mbt_score,H16,lom_text,I16,rom_score,J16,bolt_tier,IFS(bolt_score<15,0,bolt_score<=19,1,bolt_score<=24,2,bolt_score<=29,3,bolt_score<=34,4,bolt_score>=35,5,TRUE,0),co2tt_tier,IFS(co2tt_score<25,0,co2tt_score<=39,1,co2tt_score<=54,2,co2tt_score<=69,3,co2tt_score<=84,4,co2tt_score>=85,5,TRUE,0),mbt_tier,IFS(mbt_score<25,0,mbt_score<=39,1,mbt_score<=54,2,mbt_score<=69,3,mbt_score<=84,4,mbt_score>=85,5,TRUE,0),rom_tier,IFS(rom_score<60,0,rom_score<=74,1,rom_score<=89,2,rom_score<=104,3,rom_score<=119,4,rom_score>=120,5,TRUE,0),lom_tier,IFS(ISNUMBER(SEARCH("zone 3 only",lom_text)),0,ISNUMBER(SEARCH("zone 3",lom_text))*ISNUMBER(SEARCH("zone 2",lom_text)),1,ISNUMBER(SEARCH("zone 2",lom_text))*NOT(ISNUMBER(SEARCH("zone 1",lom_text)))*NOT(ISNUMBER(SEARCH("zone 3",lom_text))),2,ISNUMBER(SEARCH("zone 1",lom_text))*ISNUMBER(SEARCH("zone 2",lom_text)),3,ISNUMBER(SEARCH("zone 1",lom_text))*ISNUMBER(SEARCH("horizontal",lom_text)),4,ISNUMBER(SEARCH("360",lom_text)),5,TRUE,0),total_weighted_score,(bolt_tier*1)+(co2tt_tier*2)+(mbt_tier*3)+(lom_tier*3)+(rom_tier*1),(total_weighted_score/50)*100)) -> 46 | Q16: =IF(P16="",,IFS(P16>=93,"Ultra",P16>=80,"Great",P16>=65,"Good",P16>=50,"Fair",P16>=31,"Poor",P16>=0,"Very Poor")) -> Poor | R16: =IF(P16="",,IFS(P16>=93,"Breath Master",P16>=80,"Breathwork-Trained",P16>=65,"Functional Breather",P16>=50,"Breather-in-Training",P16>=31,"Breath Beginner",P16>=0,"Breath-Aware")) -> Breath Beginner
A17: 45919.624 | B17: Nicholas | C17: Fox | D17: nick@foxfirebreathworks.com | E17: BQ! | F17: 36 | G17: 72 | H17: 63 | I17: Zone 1 and 360° circumferential movement | J17: 91 | O17: {=IF(A17:A241="",, XLOOKUP(D17:D241, 'Recal IDs Log'!E16:E241, 'Recal IDs Log'!B16:B241, "", 0, -1))} -> #REF! | P17: =IF(A17="",,LET(bolt_score,F17,co2tt_score,G17,mbt_score,H17,lom_text,I17,rom_score,J17,bolt_tier,IFS(bolt_score<15,0,bolt_score<=19,1,bolt_score<=24,2,bolt_score<=29,3,bolt_score<=34,4,bolt_score>=35,5,TRUE,0),co2tt_tier,IFS(co2tt_score<25,0,co2tt_score<=39,1,co2tt_score<=54,2,co2tt_score<=69,3,co2tt_score<=84,4,co2tt_score>=85,5,TRUE,0),mbt_tier,IFS(mbt_score<25,0,mbt_score<=39,1,mbt_score<=54,2,mbt_score<=69,3,mbt_score<=84,4,mbt_score>=85,5,TRUE,0),rom_tier,IFS(rom_score<60,0,rom_score<=74,1,rom_score<=89,2,rom_score<=104,3,rom_score<=119,4,rom_score>=120,5,TRUE,0),lom_tier,IFS(ISNUMBER(SEARCH("zone 3 only",lom_text)),0,ISNUMBER(SEARCH("zone 3",lom_text))*ISNUMBER(SEARCH("zone 2",lom_text)),1,ISNUMBER(SEARCH("zone 2",lom_text))*NOT(ISNUMBER(SEARCH("zone 1",lom_text)))*NOT(ISNUMBER(SEARCH("zone 3",lom_text))),2,ISNUMBER(SEARCH("zone 1",lom_text))*ISNUMBER(SEARCH("zone 2",lom_text)),3,ISNUMBER(SEARCH("zone 1",lom_text))*ISNUMBER(SEARCH("horizontal",lom_text)),4,ISNUMBER(SEARCH("360",lom_text)),5,TRUE,0),total_weighted_score,(bolt_tier*1)+(co2tt_tier*2)+(mbt_tier*3)+(lom_tier*3)+(rom_tier*1),(total_weighted_score/50)*100)) -> 80 | Q17: =IF(P17="",,IFS(P17>=93,"Ultra",P17>=80,"Great",P17>=65,"Good",P17>=50,"Fair",P17>=31,"Poor",P17>=0,"Very Poor")) -> Great | R17: =IF(P17="",,IFS(P17>=93,"Breath Master",P17>=80,"Breathwork-Trained",P17>=65,"Functional Breather",P17>=50,"Breather-in-Training",P17>=31,"Breath Beginner",P17>=0,"Breath-Aware")) -> Breathwork-Trained
A18: 45925.719 | B18: Kevin | C18: Adler | D18: Kevin@thealtitudegroupinc.com | E18: Climb a high altitude mountain | F18: 22 | G18: 42 | H18: 25 | I18: Zone 1 and a bit of Zone 2, Belly movement apparent | J18: 52.6 | K18: Aconcagua in January / Denali in June | O18: {=IF(A18:A241="",, XLOOKUP(D18:D241, 'Recal IDs Log'!E17:E241, 'Recal IDs Log'!B17:B241, "", 0, -1))} -> #REF! | P18: =IF(A18="",,LET(bolt_score,F18,co2tt_score,G18,mbt_score,H18,lom_text,I18,rom_score,J18,bolt_tier,IFS(bolt_score<15,0,bolt_score<=19,1,bolt_score<=24,2,bolt_score<=29,3,bolt_score<=34,4,bolt_score>=35,5,TRUE,0),co2tt_tier,IFS(co2tt_score<25,0,co2tt_score<=39,1,co2tt_score<=54,2,co2tt_score<=69,3,co2tt_score<=84,4,co2tt_score>=85,5,TRUE,0),mbt_tier,IFS(mbt_score<25,0,mbt_score<=39,1,mbt_score<=54,2,mbt_score<=69,3,mbt_score<=84,4,mbt_score>=85,5,TRUE,0),rom_tier,IFS(rom_score<60,0,rom_score<=74,1,rom_score<=89,2,rom_score<=104,3,rom_score<=119,4,rom_score>=120,5,TRUE,0),lom_tier,IFS(ISNUMBER(SEARCH("zone 3 only",lom_text)),0,ISNUMBER(SEARCH("zone 3",lom_text))*ISNUMBER(SEARCH("zone 2",lom_text)),1,ISNUMBER(SEARCH("zone 2",lom_text))*NOT(ISNUMBER(SEARCH("zone 1",lom_text)))*NOT(ISNUMBER(SEARCH("zone 3",lom_text))),2,ISNUMBER(SEARCH("zone 1",lom_text))*ISNUMBER(SEARCH("zone 2",lom_text)),3,ISNUMBER(SEARCH("zone 1",lom_text))*ISNUMBER(SEARCH("horizontal",lom_text)),4,ISNUMBER(SEARCH("360",lom_text)),5,TRUE,0),total_weighted_score,(bolt_tier*1)+(co2tt_tier*2)+(mbt_tier*3)+(lom_tier*3)+(rom_tier*1),(total_weighted_score/50)*100)) -> 36 | Q18: =IF(P18="",,IFS(P18>=93,"Ultra",P18>=80,"Great",P18>=65,"Good",P18>=50,"Fair",P18>=31,"Poor",P18>=0,"Very Poor")) -> Poor | R18: =IF(P18="",,IFS(P18>=93,"Breath Master",P18>=80,"Breathwork-Trained",P18>=65,"Functional Breather",P18>=50,"Breather-in-Training",P18>=31,"Breath Beginner",P18>=0,"Breath-Aware")) -> Breath Beginner
A19: 45929.669 | B19: Darlene | C19: Hart | D19: lightwk@gmail.com | E19: Hiking/trekking in general | F19: 17 | G19: 24 | H19: 55 | I19: Zone 1 and a bit of Zone 2, Belly movement apparent | J19: 58 | K19: Climb Grand Teton and Take a Mountaineering class at Mt Baker or Rainier | O19: {=IF(A19:A241="",, XLOOKUP(D19:D241, 'Recal IDs Log'!E18:E241, 'Recal IDs Log'!B18:B241, "", 0, -1))} -> #REF! | P19: =IF(A19="",,LET(bolt_score,F19,co2tt_score,G19,mbt_score,H19,lom_text,I19,rom_score,J19,bolt_tier,IFS(bolt_score<15,0,bolt_score<=19,1,bolt_score<=24,2,bolt_score<=29,3,bolt_score<=34,4,bolt_score>=35,5,TRUE,0),co2tt_tier,IFS(co2tt_score<25,0,co2tt_score<=39,1,co2tt_score<=54,2,co2tt_score<=69,3,co2tt_score<=84,4,co2tt_score>=85,5,TRUE,0),mbt_tier,IFS(mbt_score<25,0,mbt_score<=39,1,mbt_score<=54,2,mbt_score<=69,3,mbt_score<=84,4,mbt_score>=85,5,TRUE,0),rom_tier,IFS(rom_score<60,0,rom_score<=74,1,rom_score<=89,2,rom_score<=104,3,rom_score<=119,4,rom_score>=120,5,TRUE,0),lom_tier,IFS(ISNUMBER(SEARCH("zone 3 only",lom_text)),0,ISNUMBER(SEARCH("zone 3",lom_text))*ISNUMBER(SEARCH("zone 2",lom_text)),1,ISNUMBER(SEARCH("zone 2",lom_text))*NOT(ISNUMBER(SEARCH("zone 1",lom_text)))*NOT(ISNUMBER(SEARCH("zone 3",lom_text))),2,ISNUMBER(SEARCH("zone 1",lom_text))*ISNUMBER(SEARCH("zone 2",lom_text)),3,ISNUMBER(SEARCH("zone 1",lom_text))*ISNUMBER(SEARCH("horizontal",lom_text)),4,ISNUMBER(SEARCH("360",lom_text)),5,TRUE,0),total_weighted_score,(bolt_tier*1)+(co2tt_tier*2)+(mbt_tier*3)+(lom_tier*3)+(rom_tier*1),(total_weighted_score/50)*100)) -> 38 | Q19: =IF(P19="",,IFS(P19>=93,"Ultra",P19>=80,"Great",P19>=65,"Good",P19>=50,"Fair",P19>=31,"Poor",P19>=0,"Very Poor")) -> Poor | R19: =IF(P19="",,IFS(P19>=93,"Breath Master",P19>=80,"Breathwork-Trained",P19>=65,"Functional Breather",P19>=50,"Breather-in-Training",P19>=31,"Breath Beginner",P19>=0,"Breath-Aware")) -> Breath Beginner
A20: 45932.896 | B20: Becki | C20: Rupp | D20: becki@trailblazerwellness.com | E20: Hiking/trekking in general | F20: 12 | G20: 30 | H20: 22 | I20: Zone 1 and a bit of Zone 2, Belly movement apparent | J20: 69.2 | K20: uphill skiing/skinning this winter at 11-13k feet above altitude | O20: {=IF(A20:A241="",, XLOOKUP(D20:D241, 'Recal IDs Log'!E19:E241, 'Recal IDs Log'!B19:B241, "", 0, -1))} -> #REF! | P20: =IF(A20="",,LET(bolt_score,F20,co2tt_score,G20,mbt_score,H20,lom_text,I20,rom_score,J20,bolt_tier,IFS(bolt_score<15,0,bolt_score<=19,1,bolt_score<=24,2,bolt_score<=29,3,bolt_score<=34,4,bolt_score>=35,5,TRUE,0),co2tt_tier,IFS(co2tt_score<25,0,co2tt_score<=39,1,co2tt_score<=54,2,co2tt_score<=69,3,co2tt_score<=84,4,co2tt_score>=85,5,TRUE,0),mbt_tier,IFS(mbt_score<25,0,mbt_score<=39,1,mbt_score<=54,2,mbt_score<=69,3,mbt_score<=84,4,mbt_score>=85,5,TRUE,0),rom_tier,IFS(rom_score<60,0,rom_score<=74,1,rom_score<=89,2,rom_score<=104,3,rom_score<=119,4,rom_score>=120,5,TRUE,0),lom_tier,IFS(ISNUMBER(SEARCH("zone 3 only",lom_text)),0,ISNUMBER(SEARCH("zone 3",lom_text))*ISNUMBER(SEARCH("zone 2",lom_text)),1,ISNUMBER(SEARCH("zone 2",lom_text))*NOT(ISNUMBER(SEARCH("zone 1",lom_text)))*NOT(ISNUMBER(SEARCH("zone 3",lom_text))),2,ISNUMBER(SEARCH("zone 1",lom_text))*ISNUMBER(SEARCH("zone 2",lom_text)),3,ISNUMBER(SEARCH("zone 1",lom_text))*ISNUMBER(SEARCH("horizontal",lom_text)),4,ISNUMBER(SEARCH("360",lom_text)),5,TRUE,0),total_weighted_score,(bolt_tier*1)+(co2tt_tier*2)+(mbt_tier*3)+(lom_tier*3)+(rom_tier*1),(total_weighted_score/50)*100)) -> 24 | Q20: =IF(P20="",,IFS(P20>=93,"Ultra",P20>=80,"Great",P20>=65,"Good",P20>=50,"Fair",P20>=31,"Poor",P20>=0,"Very Poor")) -> Very Poor | R20: =IF(P20="",,IFS(P20>=93,"Breath Master",P20>=80,"Breathwork-Trained",P20>=65,"Functional Breather",P20>=50,"Breather-in-Training",P20>=31,"Breath Beginner",P20>=0,"Breath-Aware")) -> Breath-Aware
A21: 45938.082 | B21: Nathan | C21: Tidwell | D21: nrtguard-af@yahoo.com | E21: Climb a high altitude mountain | F21: 25 | G21: 73 | H21: 70 | I21: Zone 2 | J21: 103 | K21: Aconcagua Jan/Feb 2026 | O21: {=IF(A21:A241="",, XLOOKUP(D21:D241, 'Recal IDs Log'!E20:E241, 'Recal IDs Log'!B20:B241, "", 0, -1))} -> #REF! | P21: =IF(A21="",,LET(bolt_score,F21,co2tt_score,G21,mbt_score,H21,lom_text,I21,rom_score,J21,bolt_tier,IFS(bolt_score<15,0,bolt_score<=19,1,bolt_score<=24,2,bolt_score<=29,3,bolt_score<=34,4,bolt_score>=35,5,TRUE,0),co2tt_tier,IFS(co2tt_score<25,0,co2tt_score<=39,1,co2tt_score<=54,2,co2tt_score<=69,3,co2tt_score<=84,4,co2tt_score>=85,5,TRUE,0),mbt_tier,IFS(mbt_score<25,0,mbt_score<=39,1,mbt_score<=54,2,mbt_score<=69,3,mbt_score<=84,4,mbt_score>=85,5,TRUE,0),rom_tier,IFS(rom_score<60,0,rom_score<=74,1,rom_score<=89,2,rom_score<=104,3,rom_score<=119,4,rom_score>=120,5,TRUE,0),lom_tier,IFS(ISNUMBER(SEARCH("zone 3 only",lom_text)),0,ISNUMBER(SEARCH("zone 3",lom_text))*ISNUMBER(SEARCH("zone 2",lom_text)),1,ISNUMBER(SEARCH("zone 2",lom_text))*NOT(ISNUMBER(SEARCH("zone 1",lom_text)))*NOT(ISNUMBER(SEARCH("zone 3",lom_text))),2,ISNUMBER(SEARCH("zone 1",lom_text))*ISNUMBER(SEARCH("zone 2",lom_text)),3,ISNUMBER(SEARCH("zone 1",lom_text))*ISNUMBER(SEARCH("horizontal",lom_text)),4,ISNUMBER(SEARCH("360",lom_text)),5,TRUE,0),total_weighted_score,(bolt_tier*1)+(co2tt_tier*2)+(mbt_tier*3)+(lom_tier*3)+(rom_tier*1),(total_weighted_score/50)*100)) -> 64 | Q21: =IF(P21="",,IFS(P21>=93,"Ultra",P21>=80,"Great",P21>=65,"Good",P21>=50,"Fair",P21>=31,"Poor",P21>=0,"Very Poor")) -> Fair | R21: =IF(P21="",,IFS(P21>=93,"Breath Master",P21>=80,"Breathwork-Trained",P21>=65,"Functional Breather",P21>=50,"Breather-in-Training",P21>=31,"Breath Beginner",P21>=0,"Breath-Aware")) -> Breather-in-Training
A22: 45938.807 | B22: Alex | C22: Uy | D22: alex_uy@hotmail.com | E22: Climb a high altitude mountain | F22: 32 | G22: 88 | H22: 75 | I22: Zone 1, Horizontal movement, Shoulders = no movement | J22: 96.77 | K22: Aconcagua in December | O22: {=IF(A22:A241="",, XLOOKUP(D22:D241, 'Recal IDs Log'!E21:E241, 'Recal IDs Log'!B21:B241, "", 0, -1))} -> #REF! | P22: =IF(A22="",,LET(bolt_score,F22,co2tt_score,G22,mbt_score,H22,lom_text,I22,rom_score,J22,bolt_tier,IFS(bolt_score<15,0,bolt_score<=19,1,bolt_score<=24,2,bolt_score<=29,3,bolt_score<=34,4,bolt_score>=35,5,TRUE,0),co2tt_tier,IFS(co2tt_score<25,0,co2tt_score<=39,1,co2tt_score<=54,2,co2tt_score<=69,3,co2tt_score<=84,4,co2tt_score>=85,5,TRUE,0),mbt_tier,IFS(mbt_score<25,0,mbt_score<=39,1,mbt_score<=54,2,mbt_score<=69,3,mbt_score<=84,4,mbt_score>=85,5,TRUE,0),rom_tier,IFS(rom_score<60,0,rom_score<=74,1,rom_score<=89,2,rom_score<=104,3,rom_score<=119,4,rom_score>=120,5,TRUE,0),lom_tier,IFS(ISNUMBER(SEARCH("zone 3 only",lom_text)),0,ISNUMBER(SEARCH("zone 3",lom_text))*ISNUMBER(SEARCH("zone 2",lom_text)),1,ISNUMBER(SEARCH("zone 2",lom_text))*NOT(ISNUMBER(SEARCH("zone 1",lom_text)))*NOT(ISNUMBER(SEARCH("zone 3",lom_text))),2,ISNUMBER(SEARCH("zone 1",lom_text))*ISNUMBER(SEARCH("zone 2",lom_text)),3,ISNUMBER(SEARCH("zone 1",lom_text))*ISNUMBER(SEARCH("horizontal",lom_text)),4,ISNUMBER(SEARCH("360",lom_text)),5,TRUE,0),total_weighted_score,(bolt_tier*1)+(co2tt_tier*2)+(mbt_tier*3)+(lom_tier*3)+(rom_tier*1),(total_weighted_score/50)*100)) -> 82 | Q22: =IF(P22="",,IFS(P22>=93,"Ultra",P22>=80,"Great",P22>=65,"Good",P22>=50,"Fair",P22>=31,"Poor",P22>=0,"Very Poor")) -> Great | R22: =IF(P22="",,IFS(P22>=93,"Breath Master",P22>=80,"Breathwork-Trained",P22>=65,"Functional Breather",P22>=50,"Breather-in-Training",P22>=31,"Breath Beginner",P22>=0,"Breath-Aware")) -> Breathwork-Trained
A23: 45939.344 | B23: Christyna | C23: jauffret | D23: tynasmith@icloud.com | E23: Climb a high altitude mountain | F23: 30 | G23: 61 | H23: 32 | I23: Zone 1 and a bit of Zone 2, Belly movement apparent | J23: 146.6 | K23: aconcagua in 10 weeks | O23: {=IF(A23:A241="",, XLOOKUP(D23:D241, 'Recal IDs Log'!E22:E241, 'Recal IDs Log'!B22:B241, "", 0, -1))} -> #REF! | P23: =IF(A23="",,LET(bolt_score,F23,co2tt_score,G23,mbt_score,H23,lom_text,I23,rom_score,J23,bolt_tier,IFS(bolt_score<15,0,bolt_score<=19,1,bolt_score<=24,2,bolt_score<=29,3,bolt_score<=34,4,bolt_score>=35,5,TRUE,0),co2tt_tier,IFS(co2tt_score<25,0,co2tt_score<=39,1,co2tt_score<=54,2,co2tt_score<=69,3,co2tt_score<=84,4,co2tt_score>=85,5,TRUE,0),mbt_tier,IFS(mbt_score<25,0,mbt_score<=39,1,mbt_score<=54,2,mbt_score<=69,3,mbt_score<=84,4,mbt_score>=85,5,TRUE,0),rom_tier,IFS(rom_score<60,0,rom_score<=74,1,rom_score<=89,2,rom_score<=104,3,rom_score<=119,4,rom_score>=120,5,TRUE,0),lom_tier,IFS(ISNUMBER(SEARCH("zone 3 only",lom_text)),0,ISNUMBER(SEARCH("zone 3",lom_text))*ISNUMBER(SEARCH("zone 2",lom_text)),1,ISNUMBER(SEARCH("zone 2",lom_text))*NOT(ISNUMBER(SEARCH("zone 1",lom_text)))*NOT(ISNUMBER(SEARCH("zone 3",lom_text))),2,ISNUMBER(SEARCH("zone 1",lom_text))*ISNUMBER(SEARCH("zone 2",lom_text)),3,ISNUMBER(SEARCH("zone 1",lom_text))*ISNUMBER(SEARCH("horizontal",lom_text)),4,ISNUMBER(SEARCH("360",lom_text)),5,TRUE,0),total_weighted_score,(bolt_tier*1)+(co2tt_tier*2)+(mbt_tier*3)+(lom_tier*3)+(rom_tier*1),(total_weighted_score/50)*100)) -> 54 | Q23: =IF(P23="",,IFS(P23>=93,"Ultra",P23>=80,"Great",P23>=65,"Good",P23>=50,"Fair",P23>=31,"Poor",P23>=0,"Very Poor")) -> Fair | R23: =IF(P23="",,IFS(P23>=93,"Breath Master",P23>=80,"Breathwork-Trained",P23>=65,"Functional Breather",P23>=50,"Breather-in-Training",P23>=31,"Breath Beginner",P23>=0,"Breath-Aware")) -> Breather-in-Training
A24: 45939.792 | B24: Martin | C24: Kysel | D24: martin@martinkysel.com | E24: Climb a high altitude mountain | F24: 15 | G24: 32 | H24: 23 | I24: Zone 2 | J24: 80 | K24: Aconcagua in January 2026 | O24: {=IF(A24:A241="",, XLOOKUP(D24:D241, 'Recal IDs Log'!E23:E241, 'Recal IDs Log'!B23:B241, "", 0, -1))} -> #REF! | P24: =IF(A24="",,LET(bolt_score,F24,co2tt_score,G24,mbt_score,H24,lom_text,I24,rom_score,J24,bolt_tier,IFS(bolt_score<15,0,bolt_score<=19,1,bolt_score<=24,2,bolt_score<=29,3,bolt_score<=34,4,bolt_score>=35,5,TRUE,0),co2tt_tier,IFS(co2tt_score<25,0,co2tt_score<=39,1,co2tt_score<=54,2,co2tt_score<=69,3,co2tt_score<=84,4,co2tt_score>=85,5,TRUE,0),mbt_tier,IFS(mbt_score<25,0,mbt_score<=39,1,mbt_score<=54,2,mbt_score<=69,3,mbt_score<=84,4,mbt_score>=85,5,TRUE,0),rom_tier,IFS(rom_score<60,0,rom_score<=74,1,rom_score<=89,2,rom_score<=104,3,rom_score<=119,4,rom_score>=120,5,TRUE,0),lom_tier,IFS(ISNUMBER(SEARCH("zone 3 only",lom_text)),0,ISNUMBER(SEARCH("zone 3",lom_text))*ISNUMBER(SEARCH("zone 2",lom_text)),1,ISNUMBER(SEARCH("zone 2",lom_text))*NOT(ISNUMBER(SEARCH("zone 1",lom_text)))*NOT(ISNUMBER(SEARCH("zone 3",lom_text))),2,ISNUMBER(SEARCH("zone 1",lom_text))*ISNUMBER(SEARCH("zone 2",lom_text)),3,ISNUMBER(SEARCH("zone 1",lom_text))*ISNUMBER(SEARCH("horizontal",lom_text)),4,ISNUMBER(SEARCH("360",lom_text)),5,TRUE,0),total_weighted_score,(bolt_tier*1)+(co2tt_tier*2)+(mbt_tier*3)+(lom_tier*3)+(rom_tier*1),(total_weighted_score/50)*100)) -> 22 | Q24: =IF(P24="",,IFS(P24>=93,"Ultra",P24>=80,"Great",P24>=65,"Good",P24>=50,"Fair",P24>=31,"Poor",P24>=0,"Very Poor")) -> Very Poor | R24: =IF(P24="",,IFS(P24>=93,"Breath Master",P24>=80,"Breathwork-Trained",P24>=65,"Functional Breather",P24>=50,"Breather-in-Training",P24>=31,"Breath Beginner",P24>=0,"Breath-Aware")) -> Breath-Aware
A25: 45940.413 | B25: Nina | C25: Ostasz | D25: n.ostasz@gmail.com | E25: Climb a high altitude mountain | F25: 25 | G25: 68 | H25: 77 | I25: Zone 2 | J25: 130 | K25: ? | O25: {=IF(A25:A241="",, XLOOKUP(D25:D241, 'Recal IDs Log'!E24:E241, 'Recal IDs Log'!B24:B241, "", 0, -1))} -> #REF! | P25: =IF(A25="",,LET(bolt_score,F25,co2tt_score,G25,mbt_score,H25,lom_text,I25,rom_score,J25,bolt_tier,IFS(bolt_score<15,0,bolt_score<=19,1,bolt_score<=24,2,bolt_score<=29,3,bolt_score<=34,4,bolt_score>=35,5,TRUE,0),co2tt_tier,IFS(co2tt_score<25,0,co2tt_score<=39,1,co2tt_score<=54,2,co2tt_score<=69,3,co2tt_score<=84,4,co2tt_score>=85,5,TRUE,0),mbt_tier,IFS(mbt_score<25,0,mbt_score<=39,1,mbt_score<=54,2,mbt_score<=69,3,mbt_score<=84,4,mbt_score>=85,5,TRUE,0),rom_tier,IFS(rom_score<60,0,rom_score<=74,1,rom_score<=89,2,rom_score<=104,3,rom_score<=119,4,rom_score>=120,5,TRUE,0),lom_tier,IFS(ISNUMBER(SEARCH("zone 3 only",lom_text)),0,ISNUMBER(SEARCH("zone 3",lom_text))*ISNUMBER(SEARCH("zone 2",lom_text)),1,ISNUMBER(SEARCH("zone 2",lom_text))*NOT(ISNUMBER(SEARCH("zone 1",lom_text)))*NOT(ISNUMBER(SEARCH("zone 3",lom_text))),2,ISNUMBER(SEARCH("zone 1",lom_text))*ISNUMBER(SEARCH("zone 2",lom_text)),3,ISNUMBER(SEARCH("zone 1",lom_text))*ISNUMBER(SEARCH("horizontal",lom_text)),4,ISNUMBER(SEARCH("360",lom_text)),5,TRUE,0),total_weighted_score,(bolt_tier*1)+(co2tt_tier*2)+(mbt_tier*3)+(lom_tier*3)+(rom_tier*1),(total_weighted_score/50)*100)) -> 64 | Q25: =IF(P25="",,IFS(P25>=93,"Ultra",P25>=80,"Great",P25>=65,"Good",P25>=50,"Fair",P25>=31,"Poor",P25>=0,"Very Poor")) -> Fair | R25: =IF(P25="",,IFS(P25>=93,"Breath Master",P25>=80,"Breathwork-Trained",P25>=65,"Functional Breather",P25>=50,"Breather-in-Training",P25>=31,"Breath Beginner",P25>=0,"Breath-Aware")) -> Breather-in-Training
A26: 45940.952 | B26: Zoe | C26: Nance | D26: zoe@zoefitness.com | E26: Climb a high altitude mountain | F26: 20 | G26: 45 | H26: 25 | I26: Zone 2 | J26: 46 | K26: Improve my overall breathing. Improve postural muscles in my abdomen area. Climb mountains all the time, like riding my bike up them actually :) And hiking sometimes. LOL | O26: {=IF(A26:A241="",, XLOOKUP(D26:D241, 'Recal IDs Log'!E25:E241, 'Recal IDs Log'!B25:B241, "", 0, -1))} -> #REF! | P26: =IF(A26="",,LET(bolt_score,F26,co2tt_score,G26,mbt_score,H26,lom_text,I26,rom_score,J26,bolt_tier,IFS(bolt_score<15,0,bolt_score<=19,1,bolt_score<=24,2,bolt_score<=29,3,bolt_score<=34,4,bolt_score>=35,5,TRUE,0),co2tt_tier,IFS(co2tt_score<25,0,co2tt_score<=39,1,co2tt_score<=54,2,co2tt_score<=69,3,co2tt_score<=84,4,co2tt_score>=85,5,TRUE,0),mbt_tier,IFS(mbt_score<25,0,mbt_score<=39,1,mbt_score<=54,2,mbt_score<=69,3,mbt_score<=84,4,mbt_score>=85,5,TRUE,0),rom_tier,IFS(rom_score<60,0,rom_score<=74,1,rom_score<=89,2,rom_score<=104,3,rom_score<=119,4,rom_score>=120,5,TRUE,0),lom_tier,IFS(ISNUMBER(SEARCH("zone 3 only",lom_text)),0,ISNUMBER(SEARCH("zone 3",lom_text))*ISNUMBER(SEARCH("zone 2",lom_text)),1,ISNUMBER(SEARCH("zone 2",lom_text))*NOT(ISNUMBER(SEARCH("zone 1",lom_text)))*NOT(ISNUMBER(SEARCH("zone 3",lom_text))),2,ISNUMBER(SEARCH("zone 1",lom_text))*ISNUMBER(SEARCH("zone 2",lom_text)),3,ISNUMBER(SEARCH("zone 1",lom_text))*ISNUMBER(SEARCH("horizontal",lom_text)),4,ISNUMBER(SEARCH("360",lom_text)),5,TRUE,0),total_weighted_score,(bolt_tier*1)+(co2tt_tier*2)+(mbt_tier*3)+(lom_tier*3)+(rom_tier*1),(total_weighted_score/50)*100)) -> 30 | Q26: =IF(P26="",,IFS(P26>=93,"Ultra",P26>=80,"Great",P26>=65,"Good",P26>=50,"Fair",P26>=31,"Poor",P26>=0,"Very Poor")) -> Very Poor | R26: =IF(P26="",,IFS(P26>=93,"Breath Master",P26>=80,"Breathwork-Trained",P26>=65,"Functional Breather",P26>=50,"Breather-in-Training",P26>=31,"Breath Beginner",P26>=0,"Breath-Aware")) -> Breath-Aware
A27: 45943.649 | B27: Simon | C27: le maistre | D27: simonlemaistre@gmail.com | E27: Hiking/trekking in general | F27: 30 | G27: 54 | H27: 58 | I27: Zone 1 and a bit of Zone 2, Belly movement apparent | J27: 83 | O27: {=IF(A27:A241="",, XLOOKUP(D27:D241, 'Recal IDs Log'!E26:E241, 'Recal IDs Log'!B26:B241, "", 0, -1))} -> #REF! | P27: =IF(A27="",,LET(bolt_score,F27,co2tt_score,G27,mbt_score,H27,lom_text,I27,rom_score,J27,bolt_tier,IFS(bolt_score<15,0,bolt_score<=19,1,bolt_score<=24,2,bolt_score<=29,3,bolt_score<=34,4,bolt_score>=35,5,TRUE,0),co2tt_tier,IFS(co2tt_score<25,0,co2tt_score<=39,1,co2tt_score<=54,2,co2tt_score<=69,3,co2tt_score<=84,4,co2tt_score>=85,5,TRUE,0),mbt_tier,IFS(mbt_score<25,0,mbt_score<=39,1,mbt_score<=54,2,mbt_score<=69,3,mbt_score<=84,4,mbt_score>=85,5,TRUE,0),rom_tier,IFS(rom_score<60,0,rom_score<=74,1,rom_score<=89,2,rom_score<=104,3,rom_score<=119,4,rom_score>=120,5,TRUE,0),lom_tier,IFS(ISNUMBER(SEARCH("zone 3 only",lom_text)),0,ISNUMBER(SEARCH("zone 3",lom_text))*ISNUMBER(SEARCH("zone 2",lom_text)),1,ISNUMBER(SEARCH("zone 2",lom_text))*NOT(ISNUMBER(SEARCH("zone 1",lom_text)))*NOT(ISNUMBER(SEARCH("zone 3",lom_text))),2,ISNUMBER(SEARCH("zone 1",lom_text))*ISNUMBER(SEARCH("zone 2",lom_text)),3,ISNUMBER(SEARCH("zone 1",lom_text))*ISNUMBER(SEARCH("horizontal",lom_text)),4,ISNUMBER(SEARCH("360",lom_text)),5,TRUE,0),total_weighted_score,(bolt_tier*1)+(co2tt_tier*2)+(mbt_tier*3)+(lom_tier*3)+(rom_tier*1),(total_weighted_score/50)*100)) -> 56 | Q27: =IF(P27="",,IFS(P27>=93,"Ultra",P27>=80,"Great",P27>=65,"Good",P27>=50,"Fair",P27>=31,"Poor",P27>=0,"Very Poor")) -> Fair | R27: =IF(P27="",,IFS(P27>=93,"Breath Master",P27>=80,"Breathwork-Trained",P27>=65,"Functional Breather",P27>=50,"Breather-in-Training",P27>=31,"Breath Beginner",P27>=0,"Breath-Aware")) -> Breather-in-Training
A28: 45944.148 | B28: Stewart | C28: Hiatt | D28: stewhiatt@gmail.com | E28: Climb a high altitude mountain | F28: 21 | G28: 44 | H28: 45 | I28: Zone 1 and a bit of Zone 2, Belly movement apparent | J28: 101.4 | K28: Everest Base camp | O28: {=IF(A28:A241="",, XLOOKUP(D28:D241, 'Recal IDs Log'!E26:E241, 'Recal IDs Log'!B26:B241, "", 0, -1))} -> #REF! | P28: =IF(A28="",,LET(bolt_score,F28,co2tt_score,G28,mbt_score,H28,lom_text,I28,rom_score,J28,bolt_tier,IFS(bolt_score<15,0,bolt_score<=19,1,bolt_score<=24,2,bolt_score<=29,3,bolt_score<=34,4,bolt_score>=35,5,TRUE,0),co2tt_tier,IFS(co2tt_score<25,0,co2tt_score<=39,1,co2tt_score<=54,2,co2tt_score<=69,3,co2tt_score<=84,4,co2tt_score>=85,5,TRUE,0),mbt_tier,IFS(mbt_score<25,0,mbt_score<=39,1,mbt_score<=54,2,mbt_score<=69,3,mbt_score<=84,4,mbt_score>=85,5,TRUE,0),rom_tier,IFS(rom_score<60,0,rom_score<=74,1,rom_score<=89,2,rom_score<=104,3,rom_score<=119,4,rom_score>=120,5,TRUE,0),lom_tier,IFS(ISNUMBER(SEARCH("zone 3 only",lom_text)),0,ISNUMBER(SEARCH("zone 3",lom_text))*ISNUMBER(SEARCH("zone 2",lom_text)),1,ISNUMBER(SEARCH("zone 2",lom_text))*NOT(ISNUMBER(SEARCH("zone 1",lom_text)))*NOT(ISNUMBER(SEARCH("zone 3",lom_text))),2,ISNUMBER(SEARCH("zone 1",lom_text))*ISNUMBER(SEARCH("zone 2",lom_text)),3,ISNUMBER(SEARCH("zone 1",lom_text))*ISNUMBER(SEARCH("horizontal",lom_text)),4,ISNUMBER(SEARCH("360",lom_text)),5,TRUE,0),total_weighted_score,(bolt_tier*1)+(co2tt_tier*2)+(mbt_tier*3)+(lom_tier*3)+(rom_tier*1),(total_weighted_score/50)*100)) -> 48 | Q28: =IF(P28="",,IFS(P28>=93,"Ultra",P28>=80,"Great",P28>=65,"Good",P28>=50,"Fair",P28>=31,"Poor",P28>=0,"Very Poor")) -> Poor | R28: =IF(P28="",,IFS(P28>=93,"Breath Master",P28>=80,"Breathwork-Trained",P28>=65,"Functional Breather",P28>=50,"Breather-in-Training",P28>=31,"Breath Beginner",P28>=0,"Breath-Aware")) -> Breath Beginner
A29: 45945.52 | B29: Jan | C29: Lamka | D29: jan@lamka.cz | E29: Climb a high altitude mountain | F29: 22 | G29: 46 | H29: 64 | I29: Zone 1 and 360° circumferential movement | J29: 88 | K29: Puppet d’Or (seriously: to be able to operate comfortably at altitude) | O29: {=IF(A29:A241="",, XLOOKUP(D29:D241, 'Recal IDs Log'!E26:E241, 'Recal IDs Log'!B26:B241, "", 0, -1))} -> #REF! | P29: =IF(A29="",,LET(bolt_score,F29,co2tt_score,G29,mbt_score,H29,lom_text,I29,rom_score,J29,bolt_tier,IFS(bolt_score<15,0,bolt_score<=19,1,bolt_score<=24,2,bolt_score<=29,3,bolt_score<=34,4,bolt_score>=35,5,TRUE,0),co2tt_tier,IFS(co2tt_score<25,0,co2tt_score<=39,1,co2tt_score<=54,2,co2tt_score<=69,3,co2tt_score<=84,4,co2tt_score>=85,5,TRUE,0),mbt_tier,IFS(mbt_score<25,0,mbt_score<=39,1,mbt_score<=54,2,mbt_score<=69,3,mbt_score<=84,4,mbt_score>=85,5,TRUE,0),rom_tier,IFS(rom_score<60,0,rom_score<=74,1,rom_score<=89,2,rom_score<=104,3,rom_score<=119,4,rom_score>=120,5,TRUE,0),lom_tier,IFS(ISNUMBER(SEARCH("zone 3 only",lom_text)),0,ISNUMBER(SEARCH("zone 3",lom_text))*ISNUMBER(SEARCH("zone 2",lom_text)),1,ISNUMBER(SEARCH("zone 2",lom_text))*NOT(ISNUMBER(SEARCH("zone 1",lom_text)))*NOT(ISNUMBER(SEARCH("zone 3",lom_text))),2,ISNUMBER(SEARCH("zone 1",lom_text))*ISNUMBER(SEARCH("zone 2",lom_text)),3,ISNUMBER(SEARCH("zone 1",lom_text))*ISNUMBER(SEARCH("horizontal",lom_text)),4,ISNUMBER(SEARCH("360",lom_text)),5,TRUE,0),total_weighted_score,(bolt_tier*1)+(co2tt_tier*2)+(mbt_tier*3)+(lom_tier*3)+(rom_tier*1),(total_weighted_score/50)*100)) -> 64 | Q29: =IF(P29="",,IFS(P29>=93,"Ultra",P29>=80,"Great",P29>=65,"Good",P29>=50,"Fair",P29>=31,"Poor",P29>=0,"Very Poor")) -> Fair | R29: =IF(P29="",,IFS(P29>=93,"Breath Master",P29>=80,"Breathwork-Trained",P29>=65,"Functional Breather",P29>=50,"Breather-in-Training",P29>=31,"Breath Beginner",P29>=0,"Breath-Aware")) -> Breather-in-Training
A30: 45945.851 | B30: Maciej | C30: Nowakowski | D30: maciej@es-ab.se | E30: Climb a high altitude mountain | F30: 38 | G30: 77 | H30: 75 | I30: Zone 1 and a bit of Zone 2, Belly movement apparent | J30: 105.9 | K30: Aconcagua in January (with Grajales) | O30: {=IF(A30:A241="",, XLOOKUP(D30:D241, 'Recal IDs Log'!E26:E241, 'Recal IDs Log'!B26:B241, "", 0, -1))} -> #REF! | P30: =IF(A30="",,LET(bolt_score,F30,co2tt_score,G30,mbt_score,H30,lom_text,I30,rom_score,J30,bolt_tier,IFS(bolt_score<15,0,bolt_score<=19,1,bolt_score<=24,2,bolt_score<=29,3,bolt_score<=34,4,bolt_score>=35,5,TRUE,0),co2tt_tier,IFS(co2tt_score<25,0,co2tt_score<=39,1,co2tt_score<=54,2,co2tt_score<=69,3,co2tt_score<=84,4,co2tt_score>=85,5,TRUE,0),mbt_tier,IFS(mbt_score<25,0,mbt_score<=39,1,mbt_score<=54,2,mbt_score<=69,3,mbt_score<=84,4,mbt_score>=85,5,TRUE,0),rom_tier,IFS(rom_score<60,0,rom_score<=74,1,rom_score<=89,2,rom_score<=104,3,rom_score<=119,4,rom_score>=120,5,TRUE,0),lom_tier,IFS(ISNUMBER(SEARCH("zone 3 only",lom_text)),0,ISNUMBER(SEARCH("zone 3",lom_text))*ISNUMBER(SEARCH("zone 2",lom_text)),1,ISNUMBER(SEARCH("zone 2",lom_text))*NOT(ISNUMBER(SEARCH("zone 1",lom_text)))*NOT(ISNUMBER(SEARCH("zone 3",lom_text))),2,ISNUMBER(SEARCH("zone 1",lom_text))*ISNUMBER(SEARCH("zone 2",lom_text)),3,ISNUMBER(SEARCH("zone 1",lom_text))*ISNUMBER(SEARCH("horizontal",lom_text)),4,ISNUMBER(SEARCH("360",lom_text)),5,TRUE,0),total_weighted_score,(bolt_tier*1)+(co2tt_tier*2)+(mbt_tier*3)+(lom_tier*3)+(rom_tier*1),(total_weighted_score/50)*100)) -> 76 | Q30: =IF(P30="",,IFS(P30>=93,"Ultra",P30>=80,"Great",P30>=65,"Good",P30>=50,"Fair",P30>=31,"Poor",P30>=0,"Very Poor")) -> Good | R30: =IF(P30="",,IFS(P30>=93,"Breath Master",P30>=80,"Breathwork-Trained",P30>=65,"Functional Breather",P30>=50,"Breather-in-Training",P30>=31,"Breath Beginner",P30>=0,"Breath-Aware")) -> Functional Breather
A31: 45959.443 | B31: Adam | C31: Beardsworth | D31: beards001@gmail.com | E31: Climb a high altitude mountain | F31: 21 | G31: 36 | H31: 60 | I31: Zone 1, Horizontal movement, Shoulders = no movement | J31: 98.4 | K31: SPo2 at altitude | O31: {=IF(A31:A241="",, XLOOKUP(D31:D241, 'Recal IDs Log'!E26:E241, 'Recal IDs Log'!B26:B241, "", 0, -1))} -> #REF! | P31: =IF(A31="",,LET(bolt_score,F31,co2tt_score,G31,mbt_score,H31,lom_text,I31,rom_score,J31,bolt_tier,IFS(bolt_score<15,0,bolt_score<=19,1,bolt_score<=24,2,bolt_score<=29,3,bolt_score<=34,4,bolt_score>=35,5,TRUE,0),co2tt_tier,IFS(co2tt_score<25,0,co2tt_score<=39,1,co2tt_score<=54,2,co2tt_score<=69,3,co2tt_score<=84,4,co2tt_score>=85,5,TRUE,0),mbt_tier,IFS(mbt_score<25,0,mbt_score<=39,1,mbt_score<=54,2,mbt_score<=69,3,mbt_score<=84,4,mbt_score>=85,5,TRUE,0),rom_tier,IFS(rom_score<60,0,rom_score<=74,1,rom_score<=89,2,rom_score<=104,3,rom_score<=119,4,rom_score>=120,5,TRUE,0),lom_tier,IFS(ISNUMBER(SEARCH("zone 3 only",lom_text)),0,ISNUMBER(SEARCH("zone 3",lom_text))*ISNUMBER(SEARCH("zone 2",lom_text)),1,ISNUMBER(SEARCH("zone 2",lom_text))*NOT(ISNUMBER(SEARCH("zone 1",lom_text)))*NOT(ISNUMBER(SEARCH("zone 3",lom_text))),2,ISNUMBER(SEARCH("zone 1",lom_text))*ISNUMBER(SEARCH("zone 2",lom_text)),3,ISNUMBER(SEARCH("zone 1",lom_text))*ISNUMBER(SEARCH("horizontal",lom_text)),4,ISNUMBER(SEARCH("360",lom_text)),5,TRUE,0),total_weighted_score,(bolt_tier*1)+(co2tt_tier*2)+(mbt_tier*3)+(lom_tier*3)+(rom_tier*1),(total_weighted_score/50)*100)) -> 56 | Q31: =IF(P31="",,IFS(P31>=93,"Ultra",P31>=80,"Great",P31>=65,"Good",P31>=50,"Fair",P31>=31,"Poor",P31>=0,"Very Poor")) -> Fair | R31: =IF(P31="",,IFS(P31>=93,"Breath Master",P31>=80,"Breathwork-Trained",P31>=65,"Functional Breather",P31>=50,"Breather-in-Training",P31>=31,"Breath Beginner",P31>=0,"Breath-Aware")) -> Breather-in-Training
A32: 45960.833 | B32: Don | C32: Hickman | D32: donphickman@gmail.com | E32: Hiking/trekking in general | F32: 30 | G32: 45 | H32: 60 | I32: Zone 1, Horizontal movement, Shoulders = no movement | J32: 95.2 | K32: To hike without shortness of breath | O32: {=IF(A32:A241="",, XLOOKUP(D32:D241, 'Recal IDs Log'!E26:E241, 'Recal IDs Log'!B26:B241, "", 0, -1))} -> #REF! | P32: =IF(A32="",,LET(bolt_score,F32,co2tt_score,G32,mbt_score,H32,lom_text,I32,rom_score,J32,bolt_tier,IFS(bolt_score<15,0,bolt_score<=19,1,bolt_score<=24,2,bolt_score<=29,3,bolt_score<=34,4,bolt_score>=35,5,TRUE,0),co2tt_tier,IFS(co2tt_score<25,0,co2tt_score<=39,1,co2tt_score<=54,2,co2tt_score<=69,3,co2tt_score<=84,4,co2tt_score>=85,5,TRUE,0),mbt_tier,IFS(mbt_score<25,0,mbt_score<=39,1,mbt_score<=54,2,mbt_score<=69,3,mbt_score<=84,4,mbt_score>=85,5,TRUE,0),rom_tier,IFS(rom_score<60,0,rom_score<=74,1,rom_score<=89,2,rom_score<=104,3,rom_score<=119,4,rom_score>=120,5,TRUE,0),lom_tier,IFS(ISNUMBER(SEARCH("zone 3 only",lom_text)),0,ISNUMBER(SEARCH("zone 3",lom_text))*ISNUMBER(SEARCH("zone 2",lom_text)),1,ISNUMBER(SEARCH("zone 2",lom_text))*NOT(ISNUMBER(SEARCH("zone 1",lom_text)))*NOT(ISNUMBER(SEARCH("zone 3",lom_text))),2,ISNUMBER(SEARCH("zone 1",lom_text))*ISNUMBER(SEARCH("zone 2",lom_text)),3,ISNUMBER(SEARCH("zone 1",lom_text))*ISNUMBER(SEARCH("horizontal",lom_text)),4,ISNUMBER(SEARCH("360",lom_text)),5,TRUE,0),total_weighted_score,(bolt_tier*1)+(co2tt_tier*2)+(mbt_tier*3)+(lom_tier*3)+(rom_tier*1),(total_weighted_score/50)*100)) -> 64 | Q32: =IF(P32="",,IFS(P32>=93,"Ultra",P32>=80,"Great",P32>=65,"Good",P32>=50,"Fair",P32>=31,"Poor",P32>=0,"Very Poor")) -> Fair | R32: =IF(P32="",,IFS(P32>=93,"Breath Master",P32>=80,"Breathwork-Trained",P32>=65,"Functional Breather",P32>=50,"Breather-in-Training",P32>=31,"Breath Beginner",P32>=0,"Breath-Aware")) -> Breather-in-Training
